<?xml version="1.0" encoding="utf-8" ?>
<robot name="medrob">
    <!-- Common base for both robots -->
    <link name="world" />
    <joint name="world_joint" type="fixed">
        <parent link="world" />
        <child link="base_link" />
        <origin xyz="0 0 0" rpy="0 0 0" />
    </joint>
    <!-- ===================== ROBOT 1 (original medrob) ===================== -->
    <!-- ARM LINKS AND JOINTS (original content starts here, but without 'world' element) -->
    <link name="base_link">
        <inertial>
            <origin xyz="6.1138E-05 1.7555E-05 0.097325" rpy="0 0 0" />
            <mass value="3.6282" />
            <inertia ixx="0.0073478" ixy="4.0081E-07" ixz="4.4767E-06" iyy="0.0073429" iyz="1.1049E-06" izz="0.011821" />
        </inertial>
        <visual>
            <origin xyz="0 0 0" rpy="0 0 0" />
            <geometry>
                <mesh filename="package://cobot_mesh_loader/meshes/robot_meshes/base_link.STL" />
            </geometry>
            <material name="">
                <color rgba="0.75294 0.75294 0.75294 1" />
            </material>
        </visual>
        <collision>
            <origin xyz="0 0 0" rpy="0 0 0" />
            <geometry>
                <mesh filename="package://cobot_mesh_loader/meshes/robot_meshes/base_link.STL" />
            </geometry>
        </collision>
    </link>
    <link name="link_1">
        <inertial>
            <origin xyz="-8.8386E-05 0.022834 0.13346" rpy="0 0 0" />
            <mass value="2.5503" />
            <inertia ixx="0.0042601" ixy="-3.1693E-06" ixz="7.5868E-06" iyy="0.0049054" iyz="-6.6829E-05" izz="0.0038997" />
        </inertial>
        <visual>
            <origin xyz="0 0 0" rpy="0 0 0" />
            <geometry>
                <mesh filename="package://cobot_mesh_loader/meshes/robot_meshes/link 1.STL" />
            </geometry>
            <material name="">
                <color rgba="0.75294 0.75294 0.75294 1" />
            </material>
        </visual>
        <collision>
            <origin xyz="0 0 0" rpy="0 0 0" />
            <geometry>
                <mesh filename="package://cobot_mesh_loader/meshes/robot_meshes/link 1.STL" />
            </geometry>
        </collision>
    </link>
    <joint name="joint_1" type="revolute">
        <origin xyz="0 0 0.205" rpy="0 0 0" />
        <parent link="base_link" />
        <child link="link_1" />
        <axis xyz="0 0 -1" />
        <limit lower="-3.14159" upper="3.14159" effort="10000" velocity="1000" />
    </joint>
    <link name="link_2">
        <inertial>
            <origin xyz="-0.00017021 0.15061 -0.016973" rpy="0 0 0" />
            <mass value="1.0366" />
            <inertia ixx="0.0086581" ixy="4.2443E-06" ixz="3.3833E-07" iyy="0.0014536" iyz="-1.2083E-06" izz="0.0097684" />
        </inertial>
        <visual>
            <origin xyz="0 0 0" rpy="0 0 0" />
            <geometry>
                <mesh filename="package://cobot_mesh_loader/meshes/robot_meshes/link 2.STL" />
            </geometry>
            <material name="">
                <color rgba="0.75294 0.75294 0.75294 1" />
            </material>
        </visual>
        <collision>
            <origin xyz="0 0 0" rpy="0 0 0" />
            <geometry>
                <mesh filename="package://cobot_mesh_loader/meshes/robot_meshes/link 2.STL" />
            </geometry>
        </collision>
    </link>
    <joint name="joint_2" type="revolute">
        <origin xyz="0 0.0875 0.1498" rpy="1.5708 0 0" />
        <parent link="link_1" />
        <child link="link_2" />
        <axis xyz="0 0 -1" />
        <limit lower="-3.14159" upper="3.14159" effort="10000" velocity="1000" />
    </joint>
    <link name="link_3">
        <inertial>
            <origin xyz="-7.5516E-07 0.034461 0.069151" rpy="0 0 0" />
            <mass value="3.1645" />
            <inertia ixx="0.0042531" ixy="-2.4663E-06" ixz="6.513E-06" iyy="0.0036993" iyz="-3.96E-05" izz="0.0048772" />
        </inertial>
        <visual>
            <origin xyz="0 0 0" rpy="0 0 0" />
            <geometry>
                <mesh filename="package://cobot_mesh_loader/meshes/robot_meshes/link 3.STL" />
            </geometry>
            <material name="">
                <color rgba="0.75294 0.75294 0.75294 1" />
            </material>
        </visual>
        <collision>
            <origin xyz="0 0 0" rpy="0 0 0" />
            <geometry>
                <mesh filename="package://cobot_mesh_loader/meshes/robot_meshes/link 3.STL" />
            </geometry>
        </collision>
    </link>
    <joint name="joint_3" type="revolute">
        <origin xyz="0 0.3 0" rpy="0 0 0" />
        <parent link="link_2" />
        <child link="link_3" />
        <axis xyz="0 0 -1" />
        <limit lower="-3.14159" upper="3.14159" effort="10000" velocity="1000" />
    </joint>
    <link name="link_4">
        <inertial>
            <origin xyz="1.3303E-05 0.047648 0.10412" rpy="0 0 0" />
            <mass value="1.1746" />
            <inertia ixx="0.0014257" ixy="-2.9805E-07" ixz="-3.8E-07" iyy="0.001257" iyz="-0.00028157" izz="0.0014103" />
        </inertial>
        <visual>
            <origin xyz="0 0 0" rpy="0 0 0" />
            <geometry>
                <mesh filename="package://cobot_mesh_loader/meshes/robot_meshes/link 4.STL" />
            </geometry>
            <material name="">
                <color rgba="0.75294 0.75294 0.75294 1" />
            </material>
        </visual>
        <collision>
            <origin xyz="0 0 0" rpy="0 0 0" />
            <geometry>
                <mesh filename="package://cobot_mesh_loader/meshes/robot_meshes/link 4.STL" />
            </geometry>
        </collision>
    </link>
    <joint name="joint_4" type="revolute">
        <origin xyz="0 0.1593 0.0875" rpy="1.5708 0 3.1416" />
        <parent link="link_3" />
        <child link="link_4" />
        <axis xyz="0 0 1" />
        <limit lower="-3.14159" upper="3.14159" effort="10000" velocity="1000" />
    </joint>
    <link name="link_5">
        <inertial>
            <origin xyz="-5.6194E-05 -0.033236 0.059696" rpy="0 0 0" />
            <mass value="1.0276" />
            <inertia ixx="0.00077425" ixy="-3.0073E-07" ixz="-2.1371E-06" iyy="0.00091013" iyz="1.6623E-05" izz="0.00083086" />
        </inertial>
        <visual>
            <origin xyz="0 0 0" rpy="0 0 0" />
            <geometry>
                <mesh filename="package://cobot_mesh_loader/meshes/robot_meshes/link 5.STL" />
            </geometry>
            <material name="">
                <color rgba="0.75294 0.75294 0.75294 1" />
            </material>
        </visual>
        <collision>
            <origin xyz="0 0 0" rpy="0 0 0" />
            <geometry>
                <mesh filename="package://cobot_mesh_loader/meshes/robot_meshes/link 5.STL" />
            </geometry>
        </collision>
    </link>
    <joint name="joint_5" type="revolute">
        <origin xyz="0 0.03185 0.16105" rpy="0.5236 0 0" />
        <parent link="link_4" />
        <child link="link_5" />
        <axis xyz="0 0 -1" />
        <limit lower="-3.14159" upper="3.14159" effort="10000" velocity="1000" />
    </joint>
    <link name="end_effector">
        <inertial>
            <origin xyz="7.0245E-06 -0.00022138 -0.016847" rpy="0 0 0" />
            <mass value="0.22456" />
            <inertia ixx="0.00018968" ixy="-5.0761E-08" ixz="1.4887E-08" iyy="0.00019125" iyz="-5.5675E-07" izz="0.00032612" />
        </inertial>
        <visual>
            <origin xyz="0 0 0" rpy="0 0 0" />
            <geometry>
                <mesh filename="package://cobot_mesh_loader/meshes/robot_meshes/end effector.STL" />
            </geometry>
            <material name="">
                <color rgba="0.75294 0.75294 0.75294 1" />
            </material>
        </visual>
        <collision>
            <origin xyz="0 0 0" rpy="0 0 0" />
            <geometry>
                <mesh filename="package://cobot_mesh_loader/meshes/robot_meshes/end effector.STL" />
            </geometry>
        </collision>
    </link>
    <joint name="joint_6" type="revolute">
        <origin xyz="0 -0.1227 0.0654" rpy="1.5708 0 0" />
        <parent link="link_5" />
        <child link="end_effector" />
        <axis xyz="0 0 -1" />
        <limit lower="-3.14159" upper="3.14159" effort="10000" velocity="1000" />
    </joint>
    <!-- GRIPPER CONNECTION -->
    <joint name="gripper_base_joint" type="fixed">
        <origin xyz="0 0 0.0" rpy="0 0 1.5708" />
        <parent link="end_effector" />
        <child link="robotiq_85_base_link" />
    </joint>
    <!-- ROBOTIQ GRIPPER LINKS (original) -->
    <link name="robotiq_85_base_link">
        <inertial>
            <origin xyz="-2.3546E-10 0.00021987 0.030163" rpy="0 0 1.5708" />
            <mass value="0.30915" />
            <inertia ixx="0.00028972" ixy="-5.7879E-10" ixz="-1.8543E-06" iyy="0.00030737" iyz="1.682E-12" izz="0.00019914" />
        </inertial>
        <visual>
            <origin xyz="0 0 0" rpy="0 0 0" />
            <geometry>
                <mesh filename="package://cobot_mesh_loader/meshes/robot_meshes/robotiq_85_base_link_fine.STL" />
            </geometry>
            <material name="">
                <color rgba="0.1 0.1 0.1 1" />
            </material>
        </visual>
        <collision>
            <origin xyz="0 0 0" rpy="0 0 0" />
            <geometry>
                <mesh filename="package://cobot_mesh_loader/meshes/robot_meshes/robotiq_85_base_link_coarse.STL" />
            </geometry>
        </collision>
    </link>
    <!-- Left outer knuckle -->
    <link name="left_outer_knuckle">
        <inertial>
            <origin xyz="0.0178331863169983 3.68915177224286E-11 0.0021442477325704" rpy="0 0 0" />
            <mass value="0.00684838849434396" />
            <inertia ixx="2.66832029033166E-07" ixy="1.66142314639824E-15" ixz="1.45945633322873E-07" iyy="1.3889233257419E-06" iyz="2.82951161241588E-15" izz="1.26603336914415E-06" />
        </inertial>
        <visual>
            <origin xyz="0 0 0" rpy="0 0 0" />
            <geometry>
                <mesh filename="package://cobot_mesh_loader/meshes/robot_meshes/outer_knuckle_fine.STL" />
            </geometry>
            <material name="">
                <color rgba="0.1 0.1 0.1 1" />
            </material>
        </visual>
        <collision>
            <origin xyz="0 0 0" rpy="0 0 0" />
            <geometry>
                <mesh filename="package://cobot_mesh_loader/meshes/robot_meshes/outer_knuckle_coarse.STL" />
            </geometry>
        </collision>
    </link>
    <joint name="finger_joint" type="revolute">
        <origin xyz="0.0306011444260539 0 0.0627920162695395" rpy="0 0 0" />
        <parent link="robotiq_85_base_link" />
        <child link="left_outer_knuckle" />
        <axis xyz="0 -1 0" />
        <limit lower="0" upper="0.725" velocity="2.0" effort="1000" />
    </joint>
    <!-- Remaining gripper links (original) -->
    <link name="left_outer_finger">
        <inertial>
            <origin xyz="0.00131451599174296 2.88942057994543E-15 0.0215404163180413" rpy="0 0 0" />
            <mass value="0.0273093985570947" />
            <inertia ixx="8.51629628283022E-06" ixy="2.58174336207405E-19" ixz="3.83829504344079E-07" iyy="6.9133328065108E-06" iyz="-7.58589926143789E-19" izz="2.25006832221981E-06" />
        </inertial>
        <visual>
            <origin xyz="0 0 0" rpy="0 0 0" />
            <geometry>
                <mesh filename="package://cobot_mesh_loader/meshes/robot_meshes/outer_finger_fine.STL" />
            </geometry>
            <material name="">
                <color rgba="0.1 0.1 0.1 1" />
            </material>
        </visual>
        <collision>
            <origin xyz="0 0 0" rpy="0 0 0" />
            <geometry>
                <mesh filename="package://cobot_mesh_loader/meshes/robot_meshes/outer_finger_coarse.STL" />
            </geometry>
        </collision>
    </link>
    <joint name="left_outer_finger_joint" type="fixed">
        <origin xyz="0.0316910442266543 0 -0.00193396375724605" rpy="0 0 0" />
        <parent link="left_outer_knuckle" />
        <child link="left_outer_finger" />
        <axis xyz="0 -1 0" />
    </joint>
    <link name="left_inner_knuckle">
        <inertial>
            <origin xyz="0.017097546626628 -3.93808524389535E-10 0.0224918438201868" rpy="0 0 0" />
            <mass value="0.0110930853895903" />
            <inertia ixx="4.23392770691541E-06" ixy="5.748978936968E-15" ixz="1.78855677119788E-06" iyy="3.96548790524392E-06" iyz="1.05464666369669E-14" izz="3.24068002883007E-06" />
        </inertial>
        <visual>
            <origin xyz="0 0 0" rpy="0 0 0" />
            <geometry>
                <mesh filename="package://cobot_mesh_loader/meshes/robot_meshes/inner_knuckle_fine.STL" />
            </geometry>
            <material name="">
                <color rgba="0.1 0.1 0.1 1" />
            </material>
        </visual>
        <collision>
            <origin xyz="0 0 0" rpy="0 0 0" />
            <geometry>
                <mesh filename="package://cobot_mesh_loader/meshes/robot_meshes/inner_knuckle_coarse.STL" />
            </geometry>
        </collision>
    </link>
    <joint name="left_inner_knuckle_joint" type="revolute">
        <origin xyz="0.0127000000001501 0 0.0693074999999639" rpy="0 0 0" />
        <parent link="robotiq_85_base_link" />
        <child link="left_inner_knuckle" />
        <axis xyz="0 -1 0" />
        <limit lower="0" upper="0.8757" velocity="2.0" effort="1000" />
        <mimic joint="finger_joint" multiplier="1" offset="0" />
    </joint>
    <link name="left_inner_finger">
        <inertial>
            <origin xyz="0.0060275613594574 -6.29183141465421E-15 0.00669925693133241" rpy="0 0 0" />
            <mass value="0.00724255346165745" />
            <inertia ixx="1.47824274053603E-06" ixy="-3.94884463570303E-19" ixz="-3.45268847648622E-07" iyy="1.70064480838395E-06" iyz="3.5059838910097E-19" izz="4.77151336838364E-07" />
        </inertial>
        <visual>
            <origin xyz="0 0 0" rpy="0 0 0" />
            <geometry>
                <mesh filename="package://cobot_mesh_loader/meshes/robot_meshes/inner_finger_fine.STL" />
            </geometry>
            <material name="">
                <color rgba="0.1 0.1 0.1 1" />
            </material>
        </visual>
        <collision>
            <origin xyz="0 0 0" rpy="0 0 0" />
            <geometry>
                <mesh filename="package://cobot_mesh_loader/meshes/robot_meshes/inner_finger_coarse.STL" />
            </geometry>
        </collision>
    </link>
    <joint name="left_inner_finger_joint" type="revolute">
        <origin xyz="0.034585310861294 0 0.0454970193817975" rpy="0 0 0" />
        <parent link="left_inner_knuckle" />
        <child link="left_inner_finger" />
        <axis xyz="0 -1 0" />
        <limit lower="0" upper="0.8757" velocity="2.0" effort="1000" />
        <mimic joint="finger_joint" multiplier="-1" offset="0" />
    </joint>
    <link name="right_inner_knuckle">
        <inertial>
            <origin xyz="0.0168606186773776 3.93808471820465E-10 0.0226699950793434" rpy="0 0 0" />
            <mass value="0.0110930853895903" />
            <inertia ixx="4.27134775939882E-06" ixy="-8.53568456728898E-15" ixz="1.77774229944246E-06" iyy="3.96548790524392E-06" iyz="-8.45108024914164E-15" izz="3.20325997634666E-06" />
        </inertial>
        <visual>
            <origin xyz="0 0 0" rpy="0 0 0" />
            <geometry>
                <mesh filename="package://cobot_mesh_loader/meshes/robot_meshes/inner_knuckle_fine.STL" />
            </geometry>
            <material name="">
                <color rgba="0.1 0.1 0.1 1" />
            </material>
        </visual>
        <collision>
            <origin xyz="0 0 0" rpy="0 0 0" />
            <geometry>
                <mesh filename="package://cobot_mesh_loader/meshes/robot_meshes/inner_knuckle_coarse.STL" />
            </geometry>
        </collision>
    </link>
    <joint name="right_inner_knuckle_joint" type="revolute">
        <origin xyz="-0.0126999999998499 0 0.0693075000000361" rpy="0 0 3.14159265358979" />
        <parent link="robotiq_85_base_link" />
        <child link="right_inner_knuckle" />
        <axis xyz="0 1 0" />
        <limit lower="0" upper="0.8757" velocity="2.0" effort="1000" />
        <mimic joint="finger_joint" multiplier="-1" offset="0" />
    </joint>
    <link name="right_inner_finger">
        <inertial>
            <origin xyz="0.00602756228812038 -6.47284509480176E-15 0.00669925609578108" rpy="0 0 0" />
            <mass value="0.00724255346165744" />
            <inertia ixx="1.47824283625957E-06" ixy="-3.95952064019123E-19" ixz="-3.45268708875543E-07" iyy="1.70064480838394E-06" iyz="3.55286507960029E-19" izz="4.77151241114822E-07" />
        </inertial>
        <visual>
            <origin xyz="0 0 0" rpy="0 0 0" />
            <geometry>
                <mesh filename="package://cobot_mesh_loader/meshes/robot_meshes/inner_finger_fine.STL" />
            </geometry>
            <material name="">
                <color rgba="0.1 0.1 0.1 1" />
            </material>
        </visual>
        <collision>
            <origin xyz="0 0 0" rpy="0 0 0" />
            <geometry>
                <mesh filename="package://cobot_mesh_loader/meshes/robot_meshes/inner_finger_coarse.STL" />
            </geometry>
        </collision>
    </link>
    <joint name="right_inner_finger_joint" type="revolute">
        <origin xyz="0.0341060475457406 0 0.0458573878541688" rpy="0 0 0" />
        <parent link="right_inner_knuckle" />
        <child link="right_inner_finger" />
        <axis xyz="0 1 0" />
        <limit lower="0" upper="0.8757" velocity="2.0" effort="1000" />
        <mimic joint="finger_joint" multiplier="1" offset="0" />
    </joint>
    <link name="right_outer_knuckle">
        <inertial>
            <origin xyz="0.0178097074051638 3.60493211424024E-11 0.00233123458346721" rpy="0 0 0" />
            <mass value="0.00684838849401352" />
            <inertia ixx="2.70004361573169E-07" ixy="1.59579467624491E-15" ixz="1.56396493788199E-07" iyy="1.38892332558312E-06" iyz="2.82357800318817E-15" izz="1.26286103637978E-06" />
        </inertial>
        <visual>
            <origin xyz="0 0 0" rpy="0 0 0" />
            <geometry>
                <mesh filename="package://cobot_mesh_loader/meshes/robot_meshes/outer_knuckle_fine.STL" />
            </geometry>
            <material name="">
                <color rgba="0.1 0.1 0.1 1" />
            </material>
        </visual>
        <collision>
            <origin xyz="0 0 0" rpy="0 0 0" />
            <geometry>
                <mesh filename="package://cobot_mesh_loader/meshes/robot_meshes/outer_knuckle_coarse.STL" />
            </geometry>
        </collision>
    </link>
    <joint name="right_outer_knuckle_joint" type="revolute">
        <origin xyz="-0.0306011444258893 0 0.0627920162695395" rpy="0 0 3.14159265358979" />
        <parent link="robotiq_85_base_link" />
        <child link="right_outer_knuckle" />
        <axis xyz="0 1 0" />
        <limit lower="0" upper="0.8757" velocity="2.0" effort="1000" />
        <mimic joint="finger_joint" multiplier="-1" offset="0" />
    </joint>
    <link name="right_outer_finger">
        <inertial>
            <origin xyz="0.00108844269639009 -2.611488350845E-15 0.0215530225245502" rpy="0 0 0" />
            <mass value="0.0273093985570947" />
            <inertia ixx="8.52366028592721E-06" ixy="3.41683380899422E-19" ixz="3.18003675694284E-07" iyy="6.91333280651081E-06" iyz="7.37726682706417E-19" izz="2.24270431912283E-06" />
        </inertial>
        <visual>
            <origin xyz="0 0 0" rpy="0 0 0" />
            <geometry>
                <mesh filename="package://cobot_mesh_loader/meshes/robot_meshes/outer_finger_fine.STL" />
            </geometry>
            <material name="">
                <color rgba="0.1 0.1 0.1 1" />
            </material>
        </visual>
        <collision>
            <origin xyz="0 0 0" rpy="0 0 0" />
            <geometry>
                <mesh filename="package://cobot_mesh_loader/meshes/robot_meshes/outer_finger_coarse.STL" />
            </geometry>
        </collision>
    </link>
    <joint name="right_outer_finger_joint" type="fixed">
        <origin xyz="0.0317095909367246 0 -0.0016013564954687" rpy="0 0 0" />
        <parent link="right_outer_knuckle" />
        <child link="right_outer_finger" />
        <axis xyz="0 1 0" />
    </joint>
    <!-- Camera link and joints (original)  -->
    <link name="camera_link">
        <inertial>
            <mass value="0.1" />
            <origin xyz="0 0 0" rpy="0 0 0" />
            <inertia ixx="0.0001" ixy="0" ixz="0" iyy="0.0001" iyz="0" izz="0.0001" />
        </inertial>
        <visual>
            <origin xyz="0 0 0" rpy="0 0 0" />
            <geometry>
                <box size="0.03 0.1 0.03" />
            </geometry>
            <material name="realsense_color">
                <color rgba="0.1 0.1 0.1 1" />
            </material>
        </visual>
        <collision>
            <origin xyz="0 0 0" rpy="0 0 0" />
            <geometry>
                <box size="0.03 0.1 0.03" />
            </geometry>
        </collision>
    </link>
    <joint name="camera_mount_joint" type="fixed">
        <parent link="link_5" />
        <child link="camera_link" />
        <origin xyz="0 0.05 0.05" rpy="0 0 1.5708" />
    </joint>
    <link name="camera_depth_optical_frame" />
    <joint name="camera_optical_joint" type="fixed">
        <parent link="camera_link" />
        <child link="camera_depth_optical_frame" />
        <origin xyz="0 0 0" rpy="-1.5708 0 -1.5708" />
    </joint>
    <!-- TRANSMISSIONS for Robot1 -->
    <transmission name="joint1_transmission">
        <type>transmission_interface/SimpleTransmission</type>
        <joint name="joint_1">
            <hardwareInterface>hardware_interface/PositionJointInterface</hardwareInterface>
        </joint>
        <actuator name="joint1_motor">
            <mechanicalReduction>1</mechanicalReduction>
            <hardwareInterface>hardware_interface/PositionJointInterface</hardwareInterface>
        </actuator>
    </transmission>
    <transmission name="joint2_transmission">
        <type>transmission_interface/SimpleTransmission</type>
        <joint name="joint_2">
            <hardwareInterface>hardware_interface/PositionJointInterface</hardwareInterface>
        </joint>
        <actuator name="joint2_motor">
            <mechanicalReduction>1</mechanicalReduction>
            <hardwareInterface>hardware_interface/PositionJointInterface</hardwareInterface>
        </actuator>
    </transmission>
    <transmission name="joint3_transmission">
        <type>transmission_interface/SimpleTransmission</type>
        <joint name="joint_3">
            <hardwareInterface>hardware_interface/PositionJointInterface</hardwareInterface>
        </joint>
        <actuator name="joint3_motor">
            <mechanicalReduction>1</mechanicalReduction>
            <hardwareInterface>hardware_interface/PositionJointInterface</hardwareInterface>
        </actuator>
    </transmission>
    <transmission name="joint4_transmission">
        <type>transmission_interface/SimpleTransmission</type>
        <joint name="joint_4">
            <hardwareInterface>hardware_interface/PositionJointInterface</hardwareInterface>
        </joint>
        <actuator name="joint4_motor">
            <mechanicalReduction>1</mechanicalReduction>
            <hardwareInterface>hardware_interface/PositionJointInterface</hardwareInterface>
        </actuator>
    </transmission>
    <transmission name="joint5_transmission">
        <type>transmission_interface/SimpleTransmission</type>
        <joint name="joint_5">
            <hardwareInterface>hardware_interface/PositionJointInterface</hardwareInterface>
        </joint>
        <actuator name="joint5_motor">
            <mechanicalReduction>1</mechanicalReduction>
            <hardwareInterface>hardware_interface/PositionJointInterface</hardwareInterface>
        </actuator>
    </transmission>
    <transmission name="joint6_transmission">
        <type>transmission_interface/SimpleTransmission</type>
        <joint name="joint_6">
            <hardwareInterface>hardware_interface/PositionJointInterface</hardwareInterface>
        </joint>
        <actuator name="joint6_motor">
            <mechanicalReduction>1</mechanicalReduction>
            <hardwareInterface>hardware_interface/PositionJointInterface</hardwareInterface>
        </actuator>
    </transmission>
    <transmission name="finger_joint_transmission">
        <type>transmission_interface/SimpleTransmission</type>
        <joint name="finger_joint">
            <hardwareInterface>hardware_interface/PositionJointInterface</hardwareInterface>
        </joint>
        <actuator name="finger_joint_motor">
            <mechanicalReduction>1</mechanicalReduction>
            <hardwareInterface>hardware_interface/PositionJointInterface</hardwareInterface>
        </actuator>
    </transmission>
    <!-- ===================== ROBOT 2 (duplicated, prefixed with r2_) ===================== -->
    <!-- Robot2 fixed joint to dual base with X-offset 1.5m -->
    <joint name="robot2_fixed_joint" type="fixed">
        <parent link="world" />
        <child link="r2_base_link" />
        <origin xyz="1.5 0 0" rpy="0 0 0" />
    </joint>
    <!-- robot2 links & joints (duplicated & prefixed) -->
    <link name="r2_base_link">
        <inertial>
            <origin xyz="6.1138E-05 1.7555E-05 0.097325" rpy="0 0 0" />
            <mass value="3.6282" />
            <inertia ixx="0.0073478" ixy="4.0081E-07" ixz="4.4767E-06" iyy="0.0073429" iyz="1.1049E-06" izz="0.011821" />
        </inertial>
        <visual>
            <origin xyz="0 0 0" rpy="0 0 0" />
            <geometry>
                <mesh filename="package://cobot_mesh_loader/meshes/robot_meshes/base_link.STL" />
            </geometry>
            <material name="">
                <color rgba="0.75294 0.75294 0.75294 1" />
            </material>
        </visual>
        <collision>
            <origin xyz="0 0 0" rpy="0 0 0" />
            <geometry>
                <mesh filename="package://cobot_mesh_loader/meshes/robot_meshes/base_link.STL" />
            </geometry>
        </collision>
    </link>
    <link name="r2_link_1">
        <inertial>
            <origin xyz="-8.8386E-05 0.022834 0.13346" rpy="0 0 0" />
            <mass value="2.5503" />
            <inertia ixx="0.0042601" ixy="-3.1693E-06" ixz="7.5868E-06" iyy="0.0049054" iyz="-6.6829E-05" izz="0.0038997" />
        </inertial>
        <visual>
            <origin xyz="0 0 0" rpy="0 0 0" />
            <geometry>
                <mesh filename="package://cobot_mesh_loader/meshes/robot_meshes/link 1.STL" />
            </geometry>
            <material name="">
                <color rgba="0.75294 0.75294 0.75294 1" />
            </material>
        </visual>
        <collision>
            <origin xyz="0 0 0" rpy="0 0 0" />
            <geometry>
                <mesh filename="package://cobot_mesh_loader/meshes/robot_meshes/link 1.STL" />
            </geometry>
        </collision>
    </link>
    <joint name="r2_joint_1" type="revolute">
        <origin xyz="0 0 0.205" rpy="0 0 0" />
        <parent link="r2_base_link" />
        <child link="r2_link_1" />
        <axis xyz="0 0 -1" />
        <limit lower="-3.14159" upper="3.14159" effort="10000" velocity="1000" />
    </joint>
    <link name="r2_link_2">
        <inertial>
            <origin xyz="-0.00017021 0.15061 -0.016973" rpy="0 0 0" />
            <mass value="1.0366" />
            <inertia ixx="0.0086581" ixy="4.2443E-06" ixz="3.3833E-07" iyy="0.0014536" iyz="-1.2083E-06" izz="0.0097684" />
        </inertial>
        <visual>
            <origin xyz="0 0 0" rpy="0 0 0" />
            <geometry>
                <mesh filename="package://cobot_mesh_loader/meshes/robot_meshes/link 2.STL" />
            </geometry>
            <material name="">
                <color rgba="0.75294 0.75294 0.75294 1" />
            </material>
        </visual>
        <collision>
            <origin xyz="0 0 0" rpy="0 0 0" />
            <geometry>
                <mesh filename="package://cobot_mesh_loader/meshes/robot_meshes/link 2.STL" />
            </geometry>
        </collision>
    </link>
    <joint name="r2_joint_2" type="revolute">
        <origin xyz="0 0.0875 0.1498" rpy="1.5708 0 0" />
        <parent link="r2_link_1" />
        <child link="r2_link_2" />
        <axis xyz="0 0 -1" />
        <limit lower="-3.14159" upper="3.14159" effort="10000" velocity="1000" />
    </joint>
    <link name="r2_link_3">
        <inertial>
            <origin xyz="-7.5516E-07 0.034461 0.069151" rpy="0 0 0" />
            <mass value="3.1645" />
            <inertia ixx="0.0042531" ixy="-2.4663E-06" ixz="6.513E-06" iyy="0.0036993" iyz="-3.96E-05" izz="0.0048772" />
        </inertial>
        <visual>
            <origin xyz="0 0 0" rpy="0 0 0" />
            <geometry>
                <mesh filename="package://cobot_mesh_loader/meshes/robot_meshes/link 3.STL" />
            </geometry>
            <material name="">
                <color rgba="0.75294 0.75294 0.75294 1" />
            </material>
        </visual>
        <collision>
            <origin xyz="0 0 0" rpy="0 0 0" />
            <geometry>
                <mesh filename="package://cobot_mesh_loader/meshes/robot_meshes/link 3.STL" />
            </geometry>
        </collision>
    </link>
    <joint name="r2_joint_3" type="revolute">
        <origin xyz="0 0.3 0" rpy="0 0 0" />
        <parent link="r2_link_2" />
        <child link="r2_link_3" />
        <axis xyz="0 0 -1" />
        <limit lower="-3.14159" upper="3.14159" effort="10000" velocity="1000" />
    </joint>
    <link name="r2_link_4">
        <inertial>
            <origin xyz="1.3303E-05 0.047648 0.10412" rpy="0 0 0" />
            <mass value="1.1746" />
            <inertia ixx="0.0014257" ixy="-2.9805E-07" ixz="-3.8E-07" iyy="0.001257" iyz="-0.00028157" izz="0.0014103" />
        </inertial>
        <visual>
            <origin xyz="0 0 0" rpy="0 0 0" />
            <geometry>
                <mesh filename="package://cobot_mesh_loader/meshes/robot_meshes/link 4.STL" />
            </geometry>
            <material name="">
                <color rgba="0.75294 0.75294 0.75294 1" />
            </material>
        </visual>
        <collision>
            <origin xyz="0 0 0" rpy="0 0 0" />
            <geometry>
                <mesh filename="package://cobot_mesh_loader/meshes/robot_meshes/link 4.STL" />
            </geometry>
        </collision>
    </link>
    <joint name="r2_joint_4" type="revolute">
        <origin xyz="0 0.1593 0.0875" rpy="1.5708 0 3.1416" />
        <parent link="r2_link_3" />
        <child link="r2_link_4" />
        <axis xyz="0 0 1" />
        <limit lower="-3.14159" upper="3.14159" effort="10000" velocity="1000" />
    </joint>
    <link name="r2_link_5">
        <inertial>
            <origin xyz="-5.6194E-05 -0.033236 0.059696" rpy="0 0 0" />
            <mass value="1.0276" />
            <inertia ixx="0.00077425" ixy="-3.0073E-07" ixz="-2.1371E-06" iyy="0.00091013" iyz="1.6623E-05" izz="0.00083086" />
        </inertial>
        <visual>
            <origin xyz="0 0 0" rpy="0 0 0" />
            <geometry>
                <mesh filename="package://cobot_mesh_loader/meshes/robot_meshes/link 5.STL" />
            </geometry>
            <material name="">
                <color rgba="0.75294 0.75294 0.75294 1" />
            </material>
        </visual>
        <collision>
            <origin xyz="0 0 0" rpy="0 0 0" />
            <geometry>
                <mesh filename="package://cobot_mesh_loader/meshes/robot_meshes/link 5.STL" />
            </geometry>
        </collision>
    </link>
    <joint name="r2_joint_5" type="revolute">
        <origin xyz="0 0.03185 0.16105" rpy="0.5236 0 0" />
        <parent link="r2_link_4" />
        <child link="r2_link_5" />
        <axis xyz="0 0 -1" />
        <limit lower="-3.14159" upper="3.14159" effort="10000" velocity="1000" />
    </joint>
    <link name="r2_end_effector">
        <inertial>
            <origin xyz="7.0245E-06 -0.00022138 -0.016847" rpy="0 0 0" />
            <mass value="0.22456" />
            <inertia ixx="0.00018968" ixy="-5.0761E-08" ixz="1.4887E-08" iyy="0.00019125" iyz="-5.5675E-07" izz="0.00032612" />
        </inertial>
        <visual>
            <origin xyz="0 0 0" rpy="0 0 0" />
            <geometry>
                <mesh filename="package://cobot_mesh_loader/meshes/robot_meshes/end effector.STL" />
            </geometry>
            <material name="">
                <color rgba="0.75294 0.75294 0.75294 1" />
            </material>
        </visual>
        <collision>
            <origin xyz="0 0 0" rpy="0 0 0" />
            <geometry>
                <mesh filename="package://cobot_mesh_loader/meshes/robot_meshes/end effector.STL" />
            </geometry>
        </collision>
    </link>
    <joint name="r2_joint_6" type="revolute">
        <origin xyz="0 -0.1227 0.0654" rpy="1.5708 0 0" />
        <parent link="r2_link_5" />
        <child link="r2_end_effector" />
        <axis xyz="0 0 -1" />
        <limit lower="-3.14159" upper="3.14159" effort="10000" velocity="1000" />
    </joint>
    <!-- Robot2 gripper connection -->
    <joint name="r2_gripper_base_joint" type="fixed">
        <origin xyz="0 0 0.0" rpy="0 0 1.5708" />
        <parent link="r2_end_effector" />
        <child link="r2_robotiq_85_base_link" />
    </joint>
    <!-- Robot2 gripper links (duplicated) -->
    <link name="r2_robotiq_85_base_link">
        <inertial>
            <origin xyz="-2.3546E-10 0.00021987 0.030163" rpy="0 0 1.5708" />
            <mass value="0.30915" />
            <inertia ixx="0.00028972" ixy="-5.7879E-10" ixz="-1.8543E-06" iyy="0.00030737" iyz="1.682E-12" izz="0.00019914" />
        </inertial>
        <visual>
            <origin xyz="0 0 0" rpy="0 0 0" />
            <geometry>
                <mesh filename="package://cobot_mesh_loader/meshes/robot_meshes/robotiq_85_base_link_fine.STL" />
            </geometry>
            <material name="">
                <color rgba="0.1 0.1 0.1 1" />
            </material>
        </visual>
        <collision>
            <origin xyz="0 0 0" rpy="0 0 0" />
            <geometry>
                <mesh filename="package://cobot_mesh_loader/meshes/robot_meshes/robotiq_85_base_link_coarse.STL" />
            </geometry>
        </collision>
    </link>
    <link name="r2_left_outer_knuckle">
        <inertial>
            <origin xyz="0.0178331863169983 3.68915177224286E-11 0.0021442477325704" rpy="0 0 0" />
            <mass value="0.00684838849434396" />
            <inertia ixx="2.66832029033166E-07" ixy="1.66142314639824E-15" ixz="1.45945633322873E-07" iyy="1.3889233257419E-06" iyz="2.82951161241588E-15" izz="1.26603336914415E-06" />
        </inertial>
        <visual>
            <origin xyz="0 0 0" rpy="0 0 0" />
            <geometry>
                <mesh filename="package://cobot_mesh_loader/meshes/robot_meshes/outer_knuckle_fine.STL" />
            </geometry>
            <material name="">
                <color rgba="0.1 0.1 0.1 1" />
            </material>
        </visual>
        <collision>
            <origin xyz="0 0 0" rpy="0 0 0" />
            <geometry>
                <mesh filename="package://cobot_mesh_loader/meshes/robot_meshes/outer_knuckle_coarse.STL" />
            </geometry>
        </collision>
    </link>
    <joint name="r2_finger_joint" type="revolute">
        <origin xyz="0.0306011444260539 0 0.0627920162695395" rpy="0 0 0" />
        <parent link="r2_robotiq_85_base_link" />
        <child link="r2_left_outer_knuckle" />
        <axis xyz="0 -1 0" />
        <limit lower="0" upper="0.725" velocity="2.0" effort="1000" />
    </joint>
    <link name="r2_left_outer_finger">
        <inertial>
            <origin xyz="0.00131451599174296 2.88942057994543E-15 0.0215404163180413" rpy="0 0 0" />
            <mass value="0.0273093985570947" />
            <inertia ixx="8.51629628283022E-06" ixy="2.58174336207405E-19" ixz="3.83829504344079E-07" iyy="6.9133328065108E-06" iyz="-7.58589926143789E-19" izz="2.25006832221981E-06" />
        </inertial>
        <visual>
            <origin xyz="0 0 0" rpy="0 0 0" />
            <geometry>
                <mesh filename="package://cobot_mesh_loader/meshes/robot_meshes/outer_finger_fine.STL" />
            </geometry>
            <material name="">
                <color rgba="0.1 0.1 0.1 1" />
            </material>
        </visual>
        <collision>
            <origin xyz="0 0 0" rpy="0 0 0" />
            <geometry>
                <mesh filename="package://cobot_mesh_loader/meshes/robot_meshes/outer_finger_coarse.STL" />
            </geometry>
        </collision>
    </link>
    <joint name="r2_left_outer_finger_joint" type="fixed">
        <origin xyz="0.0316910442266543 0 -0.00193396375724605" rpy="0 0 0" />
        <parent link="r2_left_outer_knuckle" />
        <child link="r2_left_outer_finger" />
        <axis xyz="0 -1 0" />
    </joint>
    <link name="r2_left_inner_knuckle">
        <inertial>
            <origin xyz="0.017097546626628 -3.93808524389535E-10 0.0224918438201868" rpy="0 0 0" />
            <mass value="0.0110930853895903" />
            <inertia ixx="4.23392770691541E-06" ixy="5.748978936968E-15" ixz="1.78855677119788E-06" iyy="3.96548790524392E-06" iyz="1.05464666369669E-14" izz="3.24068002883007E-06" />
        </inertial>
        <visual>
            <origin xyz="0 0 0" rpy="0 0 0" />
            <geometry>
                <mesh filename="package://cobot_mesh_loader/meshes/robot_meshes/inner_knuckle_fine.STL" />
            </geometry>
            <material name="">
                <color rgba="0.1 0.1 0.1 1" />
            </material>
        </visual>
        <collision>
            <origin xyz="0 0 0" rpy="0 0 0" />
            <geometry>
                <mesh filename="package://cobot_mesh_loader/meshes/robot_meshes/inner_knuckle_coarse.STL" />
            </geometry>
        </collision>
    </link>
    <joint name="r2_left_inner_knuckle_joint" type="revolute">
        <origin xyz="0.0127000000001501 0 0.0693074999999639" rpy="0 0 0" />
        <parent link="r2_robotiq_85_base_link" />
        <child link="r2_left_inner_knuckle" />
        <axis xyz="0 -1 0" />
        <limit lower="0" upper="0.8757" velocity="2.0" effort="1000" />
        <mimic joint="r2_finger_joint" multiplier="1" offset="0" />
    </joint>
    <link name="r2_left_inner_finger">
        <inertial>
            <origin xyz="0.0060275613594574 -6.29183141465421E-15 0.00669925693133241" rpy="0 0 0" />
            <mass value="0.00724255346165745" />
            <inertia ixx="1.47824274053603E-06" ixy="-3.94884463570303E-19" ixz="-3.45268847648622E-07" iyy="1.70064480838395E-06" iyz="3.5059838910097E-19" izz="4.77151336838364E-07" />
        </inertial>
        <visual>
            <origin xyz="0 0 0" rpy="0 0 0" />
            <geometry>
                <mesh filename="package://cobot_mesh_loader/meshes/robot_meshes/inner_finger_fine.STL" />
            </geometry>
            <material name="">
                <color rgba="0.1 0.1 0.1 1" />
            </material>
        </visual>
        <collision>
            <origin xyz="0 0 0" rpy="0 0 0" />
            <geometry>
                <mesh filename="package://cobot_mesh_loader/meshes/robot_meshes/inner_finger_coarse.STL" />
            </geometry>
        </collision>
    </link>
    <joint name="r2_left_inner_finger_joint" type="revolute">
        <origin xyz="0.034585310861294 0 0.0454970193817975" rpy="0 0 0" />
        <parent link="r2_left_inner_knuckle" />
        <child link="r2_left_inner_finger" />
        <axis xyz="0 -1 0" />
        <limit lower="0" upper="0.8757" velocity="2.0" effort="1000" />
        <mimic joint="r2_finger_joint" multiplier="-1" offset="0" />
    </joint>
    <link name="r2_right_inner_knuckle">
        <inertial>
            <origin xyz="0.0168606186773776 3.93808471820465E-10 0.0226699950793434" rpy="0 0 0" />
            <mass value="0.0110930853895903" />
            <inertia ixx="4.27134775939882E-06" ixy="-8.53568456728898E-15" ixz="1.77774229944246E-06" iyy="3.96548790524392E-06" iyz="-8.45108024914164E-15" izz="3.20325997634666E-06" />
        </inertial>
        <visual>
            <origin xyz="0 0 0" rpy="0 0 0" />
            <geometry>
                <mesh filename="package://cobot_mesh_loader/meshes/robot_meshes/inner_knuckle_fine.STL" />
            </geometry>
            <material name="">
                <color rgba="0.1 0.1 0.1 1" />
            </material>
        </visual>
        <collision>
            <origin xyz="0 0 0" rpy="0 0 0" />
            <geometry>
                <mesh filename="package://cobot_mesh_loader/meshes/robot_meshes/inner_knuckle_coarse.STL" />
            </geometry>
        </collision>
    </link>
    <joint name="r2_right_inner_knuckle_joint" type="revolute">
        <origin xyz="-0.0126999999998499 0 0.0693075000000361" rpy="0 0 3.14159265358979" />
        <parent link="r2_robotiq_85_base_link" />
        <child link="r2_right_inner_knuckle" />
        <axis xyz="0 1 0" />
        <limit lower="0" upper="0.8757" velocity="2.0" effort="1000" />
        <mimic joint="r2_finger_joint" multiplier="-1" offset="0" />
    </joint>
    <link name="r2_right_inner_finger">
        <inertial>
            <origin xyz="0.00602756228812038 -6.47284509480176E-15 0.00669925609578108" rpy="0 0 0" />
            <mass value="0.00724255346165744" />
            <inertia ixx="1.47824283625957E-06" ixy="-3.95952064019123E-19" ixz="-3.45268708875543E-07" iyy="1.70064480838394E-06" iyz="3.55286507960029E-19" izz="4.77151241114822E-07" />
        </inertial>
        <visual>
            <origin xyz="0 0 0" rpy="0 0 0" />
            <geometry>
                <mesh filename="package://cobot_mesh_loader/meshes/robot_meshes/inner_finger_fine.STL" />
            </geometry>
            <material name="">
                <color rgba="0.1 0.1 0.1 1" />
            </material>
        </visual>
        <collision>
            <origin xyz="0 0 0" rpy="0 0 0" />
            <geometry>
                <mesh filename="package://cobot_mesh_loader/meshes/robot_meshes/inner_finger_coarse.STL" />
            </geometry>
        </collision>
    </link>
    <joint name="r2_right_inner_finger_joint" type="revolute">
        <origin xyz="0.0341060475457406 0 0.0458573878541688" rpy="0 0 0" />
        <parent link="r2_right_inner_knuckle" />
        <child link="r2_right_inner_finger" />
        <axis xyz="0 1 0" />
        <limit lower="0" upper="0.8757" velocity="2.0" effort="1000" />
        <mimic joint="r2_finger_joint" multiplier="1" offset="0" />
    </joint>
    <link name="r2_right_outer_knuckle">
        <inertial>
            <origin xyz="0.0178097074051638 3.60493211424024E-11 0.00233123458346721" rpy="0 0 0" />
            <mass value="0.00684838849401352" />
            <inertia ixx="2.70004361573169E-07" ixy="1.59579467624491E-15" ixz="1.56396493788199E-07" iyy="1.38892332558312E-06" iyz="2.82357800318817E-15" izz="1.26286103637978E-06" />
        </inertial>
        <visual>
            <origin xyz="0 0 0" rpy="0 0 0" />
            <geometry>
                <mesh filename="package://cobot_mesh_loader/meshes/robot_meshes/outer_knuckle_fine.STL" />
            </geometry>
            <material name="">
                <color rgba="0.1 0.1 0.1 1" />
            </material>
        </visual>
        <collision>
            <origin xyz="0 0 0" rpy="0 0 0" />
            <geometry>
                <mesh filename="package://cobot_mesh_loader/meshes/robot_meshes/outer_knuckle_coarse.STL" />
            </geometry>
        </collision>
    </link>
    <joint name="r2_right_outer_knuckle_joint" type="revolute">
        <origin xyz="-0.0306011444258893 0 0.0627920162695395" rpy="0 0 3.14159265358979" />
        <parent link="r2_robotiq_85_base_link" />
        <child link="r2_right_outer_knuckle" />
        <axis xyz="0 1 0" />
        <limit lower="0" upper="0.8757" velocity="2.0" effort="1000" />
        <mimic joint="r2_finger_joint" multiplier="-1" offset="0" />
    </joint>
    <link name="r2_right_outer_finger">
        <inertial>
            <origin xyz="0.00108844269639009 -2.611488350845E-15 0.0215530225245502" rpy="0 0 0" />
            <mass value="0.0273093985570947" />
            <inertia ixx="8.52366028592721E-06" ixy="3.41683380899422E-19" ixz="3.18003675694284E-07" iyy="6.91333280651081E-06" iyz="7.37726682706417E-19" izz="2.24270431912283E-06" />
        </inertial>
        <visual>
            <origin xyz="0 0 0" rpy="0 0 0" />
            <geometry>
                <mesh filename="package://cobot_mesh_loader/meshes/robot_meshes/outer_finger_fine.STL" />
            </geometry>
            <material name="">
                <color rgba="0.1 0.1 0.1 1" />
            </material>
        </visual>
        <collision>
            <origin xyz="0 0 0" rpy="0 0 0" />
            <geometry>
                <mesh filename="package://cobot_mesh_loader/meshes/robot_meshes/outer_finger_coarse.STL" />
            </geometry>
        </collision>
    </link>
    <joint name="r2_right_outer_finger_joint" type="fixed">
        <origin xyz="0.0317095909367246 0 -0.0016013564954687" rpy="0 0 0" />
        <parent link="r2_right_outer_knuckle" />
        <child link="r2_right_outer_finger" />
        <axis xyz="0 1 0" />
    </joint>
    Robot2 camera link and joints
    <link name="r2_camera_link">
        <inertial>
            <mass value="0.1" />
            <origin xyz="0 0 0" rpy="0 0 0" />
            <inertia ixx="0.0001" ixy="0" ixz="0" iyy="0.0001" iyz="0" izz="0.0001" />
        </inertial>
        <visual>
            <origin xyz="0 0 0" rpy="0 0 0" />
            <geometry>
                <box size="0.03 0.1 0.03" />
            </geometry>
            <material name="realsense_color">
                <color rgba="0.1 0.1 0.1 1" />
            </material>
        </visual>
        <collision>
            <origin xyz="0 0 0" rpy="0 0 0" />
            <geometry>
                <box size="0.03 0.1 0.03" />
            </geometry>
        </collision>
    </link>
    <joint name="r2_camera_mount_joint" type="fixed">
        <parent link="r2_link_5" />
        <child link="r2_camera_link" />
        <origin xyz="0 0.05 0.05" rpy="0 0 1.5708" />
    </joint>
    <link name="r2_camera_depth_optical_frame" />
    <joint name="r2_camera_optical_joint" type="fixed">
        <parent link="r2_camera_link" />
        <child link="r2_camera_depth_optical_frame" />
        <origin xyz="0 0 0" rpy="-1.5708 0 -1.5708" />
    </joint>
    <!-- TRANSMISSIONS for Robot2 (prefixed) -->
    <transmission name="r2_joint1_transmission">
        <type>transmission_interface/SimpleTransmission</type>
        <joint name="r2_joint_1">
            <hardwareInterface>hardware_interface/PositionJointInterface</hardwareInterface>
        </joint>
        <actuator name="r2_joint1_motor">
            <mechanicalReduction>1</mechanicalReduction>
            <hardwareInterface>hardware_interface/PositionJointInterface</hardwareInterface>
        </actuator>
    </transmission>
    <transmission name="r2_joint2_transmission">
        <type>transmission_interface/SimpleTransmission</type>
        <joint name="r2_joint_2">
            <hardwareInterface>hardware_interface/PositionJointInterface</hardwareInterface>
        </joint>
        <actuator name="r2_joint2_motor">
            <mechanicalReduction>1</mechanicalReduction>
            <hardwareInterface>hardware_interface/PositionJointInterface</hardwareInterface>
        </actuator>
    </transmission>
    <transmission name="r2_joint3_transmission">
        <type>transmission_interface/SimpleTransmission</type>
        <joint name="r2_joint_3">
            <hardwareInterface>hardware_interface/PositionJointInterface</hardwareInterface>
        </joint>
        <actuator name="r2_joint3_motor">
            <mechanicalReduction>1</mechanicalReduction>
            <hardwareInterface>hardware_interface/PositionJointInterface</hardwareInterface>
        </actuator>
    </transmission>
    <transmission name="r2_joint4_transmission">
        <type>transmission_interface/SimpleTransmission</type>
        <joint name="r2_joint_4">
            <hardwareInterface>hardware_interface/PositionJointInterface</hardwareInterface>
        </joint>
        <actuator name="r2_joint4_motor">
            <mechanicalReduction>1</mechanicalReduction>
            <hardwareInterface>hardware_interface/PositionJointInterface</hardwareInterface>
        </actuator>
    </transmission>
    <transmission name="r2_joint5_transmission">
        <type>transmission_interface/SimpleTransmission</type>
        <joint name="r2_joint_5">
            <hardwareInterface>hardware_interface/PositionJointInterface</hardwareInterface>
        </joint>
        <actuator name="r2_joint5_motor">
            <mechanicalReduction>1</mechanicalReduction>
            <hardwareInterface>hardware_interface/PositionJointInterface</hardwareInterface>
        </actuator>
    </transmission>
    <transmission name="r2_joint6_transmission">
        <type>transmission_interface/SimpleTransmission</type>
        <joint name="r2_joint_6">
            <hardwareInterface>hardware_interface/PositionJointInterface</hardwareInterface>
        </joint>
        <actuator name="r2_joint6_motor">
            <mechanicalReduction>1</mechanicalReduction>
            <hardwareInterface>hardware_interface/PositionJointInterface</hardwareInterface>
        </actuator>
    </transmission>
    <transmission name="r2_finger_joint_transmission">
        <type>transmission_interface/SimpleTransmission</type>
        <joint name="r2_finger_joint">
            <hardwareInterface>hardware_interface/PositionJointInterface</hardwareInterface>
        </joint>
        <actuator name="r2_finger_joint_motor">
            <mechanicalReduction>1</mechanicalReduction>
            <hardwareInterface>hardware_interface/PositionJointInterface</hardwareInterface>
        </actuator>
    </transmission>
    <!-- GAZEBO PLUGIN (single plugin for the whole robot model) -->
    <gazebo>
        <plugin name="gazebo_ros_control" filename="libgazebo_ros_control.so">
            <robotSimType>gazebo_ros_control/DefaultRobotHWSim</robotSimType>
            <robotNamespace>/</robotNamespace>
        </plugin>
    </gazebo>

    <!-- <gazebo reference="end_effector">
         <plugin name="gazebo_ros_link_attacher" filename="libgazebo_ros_link_attacher.so">
            <robotNamespace>/</robotNamespace>
         </plugin>
    </gazebo> -->

    <!-- Gazebo sensor plugin for robot1 camera (original reference)
  <gazebo reference="camera_link">
    <sensor type="depth" name="realsense_camera_sensor">
      <always_on>true</always_on>
      <update_rate>30.0</update_rate>
      <camera name="camera">
        <horizontal_fov>1.047</horizontal_fov>
        <image>
          <width>640</width>
          <height>480</height>
          <format>R8G8B8</format>
        </image>
        <clip>
          <near>0.1</near>
          <far>100</far>
        </clip>
        <noise>
          <type>gaussian</type>
          <mean>0.0</mean>
          <stddev>0.007</stddev>
        </noise>
      </camera>
      <plugin name="camera_plugin" filename="libgazebo_ros_openni_kinect.so">
        <baseline>0.2</baseline>
        <robotNamespace>/robot1</robotNamespace>
        <cameraName>camera1</cameraName>
        <imageTopicName>color/image_raw</imageTopicName>
        <cameraInfoTopicName>color/camera_info</cameraInfoTopicName>
        <depthImageTopicName>depth/image_raw</depthImageTopicName>
        <depthImageCameraInfoTopicName>depth/camera_info</depthImageCameraInfoTopicName>
        <pointCloudTopicName>depth/points</pointCloudTopicName>
        <frameName>camera_depth_optical_frame</frameName>
        <pointCloudCutoff>0.1</pointCloudCutoff>
        <pointCloudCutoffMax>20.0</pointCloudCutoffMax>
        <distortionK1>0.0</distortionK1>
        <distortionK2>0.0</distortionK2>
        <distortionK3>0.0</distortionK3>
        <distortionT1>0.0</distortionT1>
        <distortionT2>0.0</distortionT2>
      </plugin>
    </sensor>
  </gazebo> -->
    <!-- Gazebo sensor plugin for robot2 camera (prefixed)
  <gazebo reference="r2_camera_link">
    <sensor type="depth" name="r2_realsense_camera_sensor">
      <always_on>true</always_on>
      <update_rate>30.0</update_rate>
      <camera name="camera">
        <horizontal_fov>1.047</horizontal_fov>
        <image>
          <width>640</width>
          <height>480</height>
          <format>R8G8B8</format>
        </image>
        <clip>
          <near>0.1</near>
          <far>100</far>
        </clip>
        <noise>
          <type>gaussian</type>
          <mean>0.0</mean>
          <stddev>0.007</stddev>
        </noise>
      </camera>
      <plugin name="r2_camera_plugin" filename="libgazebo_ros_openni_kinect.so">
        <baseline>0.2</baseline>
        <robotNamespace>/robot2</robotNamespace>
        <cameraName>camera2</cameraName>
        <imageTopicName>color/image_raw</imageTopicName>
        <cameraInfoTopicName>color/camera_info</cameraInfoTopicName>
        <depthImageTopicName>depth/image_raw</depthImageTopicName>
        <depthImageCameraInfoTopicName>depth/camera_info</depthImageCameraInfoTopicName>
        <pointCloudTopicName>depth/points</pointCloudTopicName>
        <frameName>r2_camera_depth_optical_frame</frameName>
        <pointCloudCutoff>0.1</pointCloudCutoff>
        <pointCloudCutoffMax>20.0</pointCloudCutoffMax>
        <distortionK1>0.0</distortionK1>
        <distortionK2>0.0</distortionK2>
        <distortionK3>0.0</distortionK3>
        <distortionT1>0.0</distortionT1>
        <distortionT2>0.0</distortionT2>
      </plugin>
    </sensor>
  </gazebo> -->
    <!-- GRIPPER MIMIC JOINT PLUGINS for Robot1 (original) -->
    <gazebo>
        <plugin filename="libroboticsgroup_upatras_gazebo_mimic_joint_plugin.so" name="mimic_gripper_1">
            <joint>finger_joint</joint>
            <mimicJoint>left_inner_knuckle_joint</mimicJoint>
            <multiplier>1.0</multiplier>
            <offset>0.0</offset>
        </plugin>
        <plugin filename="libroboticsgroup_upatras_gazebo_mimic_joint_plugin.so" name="mimic_gripper_2">
            <joint>finger_joint</joint>
            <mimicJoint>left_inner_finger_joint</mimicJoint>
            <multiplier>-1.0</multiplier>
            <offset>0.0</offset>
        </plugin>
        <plugin filename="libroboticsgroup_upatras_gazebo_mimic_joint_plugin.so" name="mimic_gripper_3">
            <joint>finger_joint</joint>
            <mimicJoint>right_inner_knuckle_joint</mimicJoint>
            <multiplier>-1.0</multiplier>
            <offset>0.0</offset>
        </plugin>
        <plugin filename="libroboticsgroup_upatras_gazebo_mimic_joint_plugin.so" name="mimic_gripper_4">
            <joint>finger_joint</joint>
            <mimicJoint>right_inner_finger_joint</mimicJoint>
            <multiplier>1.0</multiplier>
            <offset>0.0</offset>
        </plugin>
        <plugin filename="libroboticsgroup_upatras_gazebo_mimic_joint_plugin.so" name="mimic_gripper_5">
            <joint>finger_joint</joint>
            <mimicJoint>right_outer_knuckle_joint</mimicJoint>
            <multiplier>-1.0</multiplier>
            <offset>0.0</offset>
        </plugin>
    </gazebo>
    <!-- GRIPPER MIMIC JOINT PLUGINS for Robot2 (prefixed) -->
    <gazebo>
        <plugin filename="libroboticsgroup_upatras_gazebo_mimic_joint_plugin.so" name="r2_mimic_gripper_1">
            <joint>r2_finger_joint</joint>
            <mimicJoint>r2_left_inner_knuckle_joint</mimicJoint>
            <multiplier>1.0</multiplier>
            <offset>0.0</offset>
        </plugin>
        <plugin filename="libroboticsgroup_upatras_gazebo_mimic_joint_plugin.so" name="r2_mimic_gripper_2">
            <joint>r2_finger_joint</joint>
            <mimicJoint>r2_left_inner_finger_joint</mimicJoint>
            <multiplier>-1.0</multiplier>
            <offset>0.0</offset>
        </plugin>
        <plugin filename="libroboticsgroup_upatras_gazebo_mimic_joint_plugin.so" name="r2_mimic_gripper_3">
            <joint>r2_finger_joint</joint>
            <mimicJoint>r2_right_inner_knuckle_joint</mimicJoint>
            <multiplier>-1.0</multiplier>
            <offset>0.0</offset>
        </plugin>
        <plugin filename="libroboticsgroup_upatras_gazebo_mimic_joint_plugin.so" name="r2_mimic_gripper_4">
            <joint>r2_finger_joint</joint>
            <mimicJoint>r2_right_inner_finger_joint</mimicJoint>
            <multiplier>1.0</multiplier>
            <offset>0.0</offset>
        </plugin>
        <plugin filename="libroboticsgroup_upatras_gazebo_mimic_joint_plugin.so" name="r2_mimic_gripper_5">
            <joint>r2_finger_joint</joint>
            <mimicJoint>r2_right_outer_knuckle_joint</mimicJoint>
            <multiplier>-1.0</multiplier>
            <offset>0.0</offset>
        </plugin>
    </gazebo>
    <transmission name="trans_left_inner_knuckle_joint">
        <type>transmission_interface/SimpleTransmission</type>
        <joint name="left_inner_knuckle_joint">
            <hardwareInterface>hardware_interface/PositionJointInterface</hardwareInterface>
        </joint>
        <actuator name="left_inner_knuckle_joint_motor">
            <hardwareInterface>hardware_interface/PositionJointInterface</hardwareInterface>
            <mechanicalReduction>1</mechanicalReduction>
        </actuator>
    </transmission>
    <transmission name="trans_left_inner_finger_joint">
        <type>transmission_interface/SimpleTransmission</type>
        <joint name="left_inner_finger_joint">
            <hardwareInterface>hardware_interface/PositionJointInterface</hardwareInterface>
        </joint>
        <actuator name="left_inner_finger_joint_motor">
            <hardwareInterface>hardware_interface/PositionJointInterface</hardwareInterface>
            <mechanicalReduction>1</mechanicalReduction>
        </actuator>
    </transmission>
    <transmission name="trans_right_inner_knuckle_joint">
        <type>transmission_interface/SimpleTransmission</type>
        <joint name="right_inner_knuckle_joint">
            <hardwareInterface>hardware_interface/PositionJointInterface</hardwareInterface>
        </joint>
        <actuator name="right_inner_knuckle_joint_motor">
            <hardwareInterface>hardware_interface/PositionJointInterface</hardwareInterface>
            <mechanicalReduction>1</mechanicalReduction>
        </actuator>
    </transmission>
    <transmission name="trans_right_inner_finger_joint">
        <type>transmission_interface/SimpleTransmission</type>
        <joint name="right_inner_finger_joint">
            <hardwareInterface>hardware_interface/PositionJointInterface</hardwareInterface>
        </joint>
        <actuator name="right_inner_finger_joint_motor">
            <hardwareInterface>hardware_interface/PositionJointInterface</hardwareInterface>
            <mechanicalReduction>1</mechanicalReduction>
        </actuator>
    </transmission>
    <transmission name="trans_right_outer_knuckle_joint">
        <type>transmission_interface/SimpleTransmission</type>
        <joint name="right_outer_knuckle_joint">
            <hardwareInterface>hardware_interface/PositionJointInterface</hardwareInterface>
        </joint>
        <actuator name="right_outer_knuckle_joint_motor">
            <hardwareInterface>hardware_interface/PositionJointInterface</hardwareInterface>
            <mechanicalReduction>1</mechanicalReduction>
        </actuator>
    </transmission>
    <transmission name="trans_r2_left_inner_knuckle_joint">
        <type>transmission_interface/SimpleTransmission</type>
        <joint name="r2_left_inner_knuckle_joint">
            <hardwareInterface>hardware_interface/PositionJointInterface</hardwareInterface>
        </joint>
        <actuator name="r2_left_inner_knuckle_joint_motor">
            <hardwareInterface>hardware_interface/PositionJointInterface</hardwareInterface>
            <mechanicalReduction>1</mechanicalReduction>
        </actuator>
    </transmission>
    <transmission name="trans_r2_left_inner_finger_joint">
        <type>transmission_interface/SimpleTransmission</type>
        <joint name="r2_left_inner_finger_joint">
            <hardwareInterface>hardware_interface/PositionJointInterface</hardwareInterface>
        </joint>
        <actuator name="r2_left_inner_finger_joint_motor">
            <hardwareInterface>hardware_interface/PositionJointInterface</hardwareInterface>
            <mechanicalReduction>1</mechanicalReduction>
        </actuator>
    </transmission>
    <transmission name="trans_r2_right_inner_knuckle_joint">
        <type>transmission_interface/SimpleTransmission</type>
        <joint name="r2_right_inner_knuckle_joint">
            <hardwareInterface>hardware_interface/PositionJointInterface</hardwareInterface>
        </joint>
        <actuator name="r2_right_inner_knuckle_joint_motor">
            <hardwareInterface>hardware_interface/PositionJointInterface</hardwareInterface>
            <mechanicalReduction>1</mechanicalReduction>
        </actuator>
    </transmission>
    <transmission name="trans_r2_right_inner_finger_joint">
        <type>transmission_interface/SimpleTransmission</type>
        <joint name="r2_right_inner_finger_joint">
            <hardwareInterface>hardware_interface/PositionJointInterface</hardwareInterface>
        </joint>
        <actuator name="r2_right_inner_finger_joint_motor">
            <hardwareInterface>hardware_interface/PositionJointInterface</hardwareInterface>
            <mechanicalReduction>1</mechanicalReduction>
        </actuator>
    </transmission>
    <transmission name="trans_r2_right_outer_knuckle_joint">
        <type>transmission_interface/SimpleTransmission</type>
        <joint name="r2_right_outer_knuckle_joint">
            <hardwareInterface>hardware_interface/PositionJointInterface</hardwareInterface>
        </joint>
        <actuator name="r2_right_outer_knuckle_joint_motor">
            <hardwareInterface>hardware_interface/PositionJointInterface</hardwareInterface>
            <mechanicalReduction>1</mechanicalReduction>
        </actuator>
    </transmission>
</robot>

